[2025-03-10 08:54:56,879] {taskinstance.py:896} INFO - Dependencies all met for <TaskInstance: xkcd_daily.xkcd_data_sensor 2025-03-10T08:54:55.246888+00:00 [queued]>
[2025-03-10 08:54:56,889] {taskinstance.py:896} INFO - Dependencies all met for <TaskInstance: xkcd_daily.xkcd_data_sensor 2025-03-10T08:54:55.246888+00:00 [queued]>
[2025-03-10 08:54:56,889] {taskinstance.py:1087} INFO - 
--------------------------------------------------------------------------------
[2025-03-10 08:54:56,890] {taskinstance.py:1088} INFO - Starting attempt 1 of 2
[2025-03-10 08:54:56,890] {taskinstance.py:1089} INFO - 
--------------------------------------------------------------------------------
[2025-03-10 08:54:56,895] {taskinstance.py:1107} INFO - Executing <Task(XKCDDataSensor): xkcd_data_sensor> on 2025-03-10T08:54:55.246888+00:00
[2025-03-10 08:54:56,897] {standard_task_runner.py:52} INFO - Started process 268 to run task
[2025-03-10 08:54:56,899] {standard_task_runner.py:76} INFO - Running: ['***', 'tasks', 'run', 'xkcd_daily', 'xkcd_data_sensor', '2025-03-10T08:54:55.246888+00:00', '--job-id', '8', '--pool', 'default_pool', '--raw', '--subdir', 'DAGS_FOLDER/XKCD_daily/dag.py', '--cfg-path', '/tmp/tmpggquscgy', '--error-file', '/tmp/tmpwjjcz4vv']
[2025-03-10 08:54:56,901] {standard_task_runner.py:77} INFO - Job 8: Subtask xkcd_data_sensor
[2025-03-10 08:54:56,923] {logging_mixin.py:104} INFO - Running <TaskInstance: xkcd_daily.xkcd_data_sensor 2025-03-10T08:54:55.246888+00:00 [running]> on host 9064500c1350
[2025-03-10 08:54:56,947] {taskinstance.py:1302} INFO - Exporting the following env vars:
AIRFLOW_CTX_DAG_OWNER=***
AIRFLOW_CTX_DAG_ID=xkcd_daily
AIRFLOW_CTX_TASK_ID=xkcd_data_sensor
AIRFLOW_CTX_EXECUTION_DATE=2025-03-10T08:54:55.246888+00:00
AIRFLOW_CTX_DAG_RUN_ID=manual__2025-03-10T08:54:55.246888+00:00
[2025-03-10 08:54:56,952] {base.py:78} INFO - Using connection to: id: xkcd_api. Host: https://xkcd.com, Port: None, Schema: None, Login: None, Password: None, extra: {'endpoint': '/info.0.json'}
[2025-03-10 08:54:57,012] {taskinstance.py:1501} ERROR - Task failed with exception
Traceback (most recent call last):
  File "/home/airflow/.local/lib/python3.6/site-packages/airflow/models/taskinstance.py", line 1157, in _run_raw_task
    self._prepare_and_execute_task_with_callbacks(context, task)
  File "/home/airflow/.local/lib/python3.6/site-packages/airflow/models/taskinstance.py", line 1331, in _prepare_and_execute_task_with_callbacks
    result = self._execute_task(context, task_copy)
  File "/home/airflow/.local/lib/python3.6/site-packages/airflow/models/taskinstance.py", line 1361, in _execute_task
    result = task_copy.execute(context=context)
  File "/home/airflow/.local/lib/python3.6/site-packages/airflow/sensors/base.py", line 231, in execute
    while not self.poke(context):
  File "/usr/local/airflow/dags/XKCD_daily/dag.py", line 96, in poke
    if check_xkcd_data(xkcd_data):
  File "/usr/local/airflow/dags/XKCD_daily/dag.py", line 44, in check_xkcd_data
    xkcd_num = xkcd_data["num"]
KeyError: 'num'
[2025-03-10 08:54:57,017] {taskinstance.py:1551} INFO - Marking task as UP_FOR_RETRY. dag_id=xkcd_daily, task_id=xkcd_data_sensor, execution_date=20250310T085455, start_date=20250310T085456, end_date=20250310T085457
[2025-03-10 08:54:57,030] {local_task_job.py:149} INFO - Task exited with return code 1
