[2025-03-10 09:04:39,962] {taskinstance.py:896} INFO - Dependencies all met for <TaskInstance: xkcd_daily.fetch_xkcd_data 2025-03-10T09:04:39.350978+00:00 [queued]>
[2025-03-10 09:04:39,968] {taskinstance.py:896} INFO - Dependencies all met for <TaskInstance: xkcd_daily.fetch_xkcd_data 2025-03-10T09:04:39.350978+00:00 [queued]>
[2025-03-10 09:04:39,968] {taskinstance.py:1087} INFO - 
--------------------------------------------------------------------------------
[2025-03-10 09:04:39,968] {taskinstance.py:1088} INFO - Starting attempt 1 of 2
[2025-03-10 09:04:39,969] {taskinstance.py:1089} INFO - 
--------------------------------------------------------------------------------
[2025-03-10 09:04:39,977] {taskinstance.py:1107} INFO - Executing <Task(PythonOperator): fetch_xkcd_data> on 2025-03-10T09:04:39.350978+00:00
[2025-03-10 09:04:39,979] {standard_task_runner.py:52} INFO - Started process 169 to run task
[2025-03-10 09:04:39,981] {standard_task_runner.py:76} INFO - Running: ['***', 'tasks', 'run', 'xkcd_daily', 'fetch_xkcd_data', '2025-03-10T09:04:39.350978+00:00', '--job-id', '2', '--pool', 'default_pool', '--raw', '--subdir', 'DAGS_FOLDER/XKCD_daily/dag.py', '--cfg-path', '/tmp/tmp22lgtyek', '--error-file', '/tmp/tmp5fb5mamk']
[2025-03-10 09:04:39,982] {standard_task_runner.py:77} INFO - Job 2: Subtask fetch_xkcd_data
[2025-03-10 09:04:40,008] {logging_mixin.py:104} INFO - Running <TaskInstance: xkcd_daily.fetch_xkcd_data 2025-03-10T09:04:39.350978+00:00 [running]> on host dfff7782b6a2
[2025-03-10 09:04:40,035] {taskinstance.py:1302} INFO - Exporting the following env vars:
AIRFLOW_CTX_DAG_OWNER=***
AIRFLOW_CTX_DAG_ID=xkcd_daily
AIRFLOW_CTX_TASK_ID=fetch_xkcd_data
AIRFLOW_CTX_EXECUTION_DATE=2025-03-10T09:04:39.350978+00:00
AIRFLOW_CTX_DAG_RUN_ID=manual__2025-03-10T09:04:39.350978+00:00
[2025-03-10 09:04:40,043] {taskinstance.py:1501} ERROR - Task failed with exception
Traceback (most recent call last):
  File "/home/airflow/.local/lib/python3.6/site-packages/airflow/models/taskinstance.py", line 1157, in _run_raw_task
    self._prepare_and_execute_task_with_callbacks(context, task)
  File "/home/airflow/.local/lib/python3.6/site-packages/airflow/models/taskinstance.py", line 1331, in _prepare_and_execute_task_with_callbacks
    result = self._execute_task(context, task_copy)
  File "/home/airflow/.local/lib/python3.6/site-packages/airflow/models/taskinstance.py", line 1361, in _execute_task
    result = task_copy.execute(context=context)
  File "/home/airflow/.local/lib/python3.6/site-packages/airflow/operators/python.py", line 150, in execute
    return_value = self.execute_callable()
  File "/home/airflow/.local/lib/python3.6/site-packages/airflow/operators/python.py", line 161, in execute_callable
    return self.python_callable(*self.op_args, **self.op_kwargs)
  File "/usr/local/airflow/dags/XKCD_daily/dag.py", line 27, in fetch_xkcd_data
    connection = BaseHook.get_connection(conn_id)
  File "/home/airflow/.local/lib/python3.6/site-packages/airflow/hooks/base.py", line 67, in get_connection
    conn = Connection.get_connection_from_secrets(conn_id)
  File "/home/airflow/.local/lib/python3.6/site-packages/airflow/models/connection.py", line 379, in get_connection_from_secrets
    raise AirflowNotFoundException(f"The conn_id `{conn_id}` isn't defined")
airflow.exceptions.AirflowNotFoundException: The conn_id `xkcd_api` isn't defined
[2025-03-10 09:04:40,046] {taskinstance.py:1551} INFO - Marking task as UP_FOR_RETRY. dag_id=xkcd_daily, task_id=fetch_xkcd_data, execution_date=20250310T090439, start_date=20250310T090439, end_date=20250310T090440
[2025-03-10 09:04:40,072] {local_task_job.py:149} INFO - Task exited with return code 1
