[2025-03-10T15:43:29.554+0000] {local_task_job_runner.py:123} INFO - ::group::Pre task execution logs
[2025-03-10T15:43:29.578+0000] {taskinstance.py:2614} INFO - Dependencies all met for dep_context=non-requeueable deps ti=<TaskInstance: xkcd_daily.dbt_run manual__2025-03-10T14:20:39.848994+00:00 [queued]>
[2025-03-10T15:43:29.584+0000] {taskinstance.py:2614} INFO - Dependencies all met for dep_context=requeueable deps ti=<TaskInstance: xkcd_daily.dbt_run manual__2025-03-10T14:20:39.848994+00:00 [queued]>
[2025-03-10T15:43:29.585+0000] {taskinstance.py:2867} INFO - Starting attempt 13 of 13
[2025-03-10T15:43:29.595+0000] {taskinstance.py:2890} INFO - Executing <Task(BashOperator): dbt_run> on 2025-03-10 14:20:39.848994+00:00
[2025-03-10T15:43:29.599+0000] {logging_mixin.py:190} WARNING - /home/***/.local/lib/python3.12/site-packages/***/task/task_runner/standard_task_runner.py:70 DeprecationWarning: This process (pid=1983) is multi-threaded, use of fork() may lead to deadlocks in the child.
[2025-03-10T15:43:29.600+0000] {standard_task_runner.py:72} INFO - Started process 1984 to run task
[2025-03-10T15:43:29.600+0000] {standard_task_runner.py:104} INFO - Running: ['***', 'tasks', 'run', 'xkcd_daily', 'dbt_run', 'manual__2025-03-10T14:20:39.848994+00:00', '--job-id', '160', '--raw', '--subdir', 'DAGS_FOLDER/XKCD_daily/dag.py', '--cfg-path', '/tmp/tmpyk7quk1_']
[2025-03-10T15:43:29.606+0000] {standard_task_runner.py:105} INFO - Job 160: Subtask dbt_run
[2025-03-10T15:43:29.629+0000] {logging_mixin.py:190} WARNING - /home/***/.local/lib/python3.12/site-packages/***/settings.py:209 DeprecationWarning: The sql_alchemy_conn option in [core] has been moved to the sql_alchemy_conn option in [database] - the old setting has been used, but please update your config.
[2025-03-10T15:43:29.662+0000] {task_command.py:467} INFO - Running <TaskInstance: xkcd_daily.dbt_run manual__2025-03-10T14:20:39.848994+00:00 [running]> on host 157a64d0872f
[2025-03-10T15:43:29.729+0000] {taskinstance.py:3134} INFO - Exporting env vars: AIRFLOW_CTX_DAG_OWNER='***' AIRFLOW_CTX_DAG_ID='xkcd_daily' AIRFLOW_CTX_TASK_ID='dbt_run' AIRFLOW_CTX_EXECUTION_DATE='2025-03-10T14:20:39.848994+00:00' AIRFLOW_CTX_TRY_NUMBER='13' AIRFLOW_CTX_DAG_RUN_ID='manual__2025-03-10T14:20:39.848994+00:00'
[2025-03-10T15:43:29.730+0000] {taskinstance.py:732} INFO - ::endgroup::
[2025-03-10T15:43:29.739+0000] {subprocess.py:78} INFO - Tmp dir root location: /tmp
[2025-03-10T15:43:29.740+0000] {subprocess.py:88} INFO - Running command: ['/usr/bin/bash', '-c', 'cd /dbt/transformations && dbt run --project-dir /dbt/transformations --profiles-dir /dbt']
[2025-03-10T15:43:29.746+0000] {subprocess.py:99} INFO - Output:
[2025-03-10T15:43:31.298+0000] {subprocess.py:106} INFO - [0m15:43:31  Running with dbt=1.9.3
[2025-03-10T15:43:31.519+0000] {subprocess.py:106} INFO - [0m15:43:31  Registered adapter: postgres=1.9.0
[2025-03-10T15:43:31.912+0000] {subprocess.py:106} INFO - [0m15:43:31  Encountered an error:
[2025-03-10T15:43:31.913+0000] {subprocess.py:106} INFO - Compilation Error
[2025-03-10T15:43:31.913+0000] {subprocess.py:106} INFO -   Model 'model.transformations.dm_comic_overview' (models/comics/dm_comic_overview.sql) depends on a node named 'dim_comic' which was not found
[2025-03-10T15:43:32.481+0000] {subprocess.py:110} INFO - Command exited with return code 2
[2025-03-10T15:43:32.496+0000] {taskinstance.py:3313} ERROR - Task failed with exception
Traceback (most recent call last):
  File "/home/airflow/.local/lib/python3.12/site-packages/airflow/models/taskinstance.py", line 768, in _execute_task
    result = _execute_callable(context=context, **execute_callable_kwargs)
             ^^^^^^^^^^^^^^^^^^^^^^^^^^^^^^^^^^^^^^^^^^^^^^^^^^^^^^^^^^^^^
  File "/home/airflow/.local/lib/python3.12/site-packages/airflow/models/taskinstance.py", line 734, in _execute_callable
    return ExecutionCallableRunner(
           ^^^^^^^^^^^^^^^^^^^^^^^^
  File "/home/airflow/.local/lib/python3.12/site-packages/airflow/utils/operator_helpers.py", line 252, in run
    return self.func(*args, **kwargs)
           ^^^^^^^^^^^^^^^^^^^^^^^^^^
  File "/home/airflow/.local/lib/python3.12/site-packages/airflow/models/baseoperator.py", line 424, in wrapper
    return func(self, *args, **kwargs)
           ^^^^^^^^^^^^^^^^^^^^^^^^^^^
  File "/home/airflow/.local/lib/python3.12/site-packages/airflow/operators/bash.py", line 276, in execute
    raise AirflowException(
airflow.exceptions.AirflowException: Bash command failed. The command returned a non-zero exit code 2.
[2025-03-10T15:43:32.499+0000] {taskinstance.py:1226} INFO - Marking task as FAILED. dag_id=xkcd_daily, task_id=dbt_run, run_id=manual__2025-03-10T14:20:39.848994+00:00, execution_date=20250310T142039, start_date=20250310T154329, end_date=20250310T154332
[2025-03-10T15:43:32.568+0000] {taskinstance.py:341} INFO - ::group::Post task execution logs
[2025-03-10T15:43:32.568+0000] {standard_task_runner.py:124} ERROR - Failed to execute job 160 for task dbt_run (Bash command failed. The command returned a non-zero exit code 2.; 1984)
Traceback (most recent call last):
  File "/home/airflow/.local/lib/python3.12/site-packages/airflow/task/task_runner/standard_task_runner.py", line 117, in _start_by_fork
    ret = args.func(args, dag=self.dag)
          ^^^^^^^^^^^^^^^^^^^^^^^^^^^^^
  File "/home/airflow/.local/lib/python3.12/site-packages/airflow/cli/cli_config.py", line 49, in command
    return func(*args, **kwargs)
           ^^^^^^^^^^^^^^^^^^^^^
  File "/home/airflow/.local/lib/python3.12/site-packages/airflow/utils/cli.py", line 116, in wrapper
    return f(*args, **kwargs)
           ^^^^^^^^^^^^^^^^^^
  File "/home/airflow/.local/lib/python3.12/site-packages/airflow/cli/commands/task_command.py", line 483, in task_run
    task_return_code = _run_task_by_selected_method(args, _dag, ti)
                       ^^^^^^^^^^^^^^^^^^^^^^^^^^^^^^^^^^^^^^^^^^^^
  File "/home/airflow/.local/lib/python3.12/site-packages/airflow/cli/commands/task_command.py", line 256, in _run_task_by_selected_method
    return _run_raw_task(args, ti)
           ^^^^^^^^^^^^^^^^^^^^^^^
  File "/home/airflow/.local/lib/python3.12/site-packages/airflow/cli/commands/task_command.py", line 341, in _run_raw_task
    return ti._run_raw_task(
           ^^^^^^^^^^^^^^^^^
  File "/home/airflow/.local/lib/python3.12/site-packages/airflow/utils/session.py", line 97, in wrapper
    return func(*args, session=session, **kwargs)
           ^^^^^^^^^^^^^^^^^^^^^^^^^^^^^^^^^^^^^^
  File "/home/airflow/.local/lib/python3.12/site-packages/airflow/models/taskinstance.py", line 3006, in _run_raw_task
    return _run_raw_task(
           ^^^^^^^^^^^^^^
  File "/home/airflow/.local/lib/python3.12/site-packages/airflow/models/taskinstance.py", line 274, in _run_raw_task
    TaskInstance._execute_task_with_callbacks(
  File "/home/airflow/.local/lib/python3.12/site-packages/airflow/models/taskinstance.py", line 3161, in _execute_task_with_callbacks
    result = self._execute_task(context, task_orig)
             ^^^^^^^^^^^^^^^^^^^^^^^^^^^^^^^^^^^^^^
  File "/home/airflow/.local/lib/python3.12/site-packages/airflow/models/taskinstance.py", line 3185, in _execute_task
    return _execute_task(self, context, task_orig)
           ^^^^^^^^^^^^^^^^^^^^^^^^^^^^^^^^^^^^^^^
  File "/home/airflow/.local/lib/python3.12/site-packages/airflow/models/taskinstance.py", line 768, in _execute_task
    result = _execute_callable(context=context, **execute_callable_kwargs)
             ^^^^^^^^^^^^^^^^^^^^^^^^^^^^^^^^^^^^^^^^^^^^^^^^^^^^^^^^^^^^^
  File "/home/airflow/.local/lib/python3.12/site-packages/airflow/models/taskinstance.py", line 734, in _execute_callable
    return ExecutionCallableRunner(
           ^^^^^^^^^^^^^^^^^^^^^^^^
  File "/home/airflow/.local/lib/python3.12/site-packages/airflow/utils/operator_helpers.py", line 252, in run
    return self.func(*args, **kwargs)
           ^^^^^^^^^^^^^^^^^^^^^^^^^^
  File "/home/airflow/.local/lib/python3.12/site-packages/airflow/models/baseoperator.py", line 424, in wrapper
    return func(self, *args, **kwargs)
           ^^^^^^^^^^^^^^^^^^^^^^^^^^^
  File "/home/airflow/.local/lib/python3.12/site-packages/airflow/operators/bash.py", line 276, in execute
    raise AirflowException(
airflow.exceptions.AirflowException: Bash command failed. The command returned a non-zero exit code 2.
[2025-03-10T15:43:32.589+0000] {local_task_job_runner.py:266} INFO - Task exited with return code 1
[2025-03-10T15:43:32.617+0000] {taskinstance.py:3901} INFO - 0 downstream tasks scheduled from follow-on schedule check
[2025-03-10T15:43:32.620+0000] {local_task_job_runner.py:245} INFO - ::endgroup::
