[2025-03-10T16:20:59.357+0000] {local_task_job_runner.py:123} INFO - ::group::Pre task execution logs
[2025-03-10T16:20:59.378+0000] {taskinstance.py:2614} INFO - Dependencies all met for dep_context=non-requeueable deps ti=<TaskInstance: xkcd_daily.dbt_run manual__2025-03-10T14:20:39.848994+00:00 [queued]>
[2025-03-10T16:20:59.384+0000] {taskinstance.py:2614} INFO - Dependencies all met for dep_context=requeueable deps ti=<TaskInstance: xkcd_daily.dbt_run manual__2025-03-10T14:20:39.848994+00:00 [queued]>
[2025-03-10T16:20:59.385+0000] {taskinstance.py:2867} INFO - Starting attempt 14 of 15
[2025-03-10T16:20:59.394+0000] {taskinstance.py:2890} INFO - Executing <Task(BashOperator): dbt_run> on 2025-03-10 14:20:39.848994+00:00
[2025-03-10T16:20:59.399+0000] {logging_mixin.py:190} WARNING - /home/***/.local/lib/python3.12/site-packages/***/task/task_runner/standard_task_runner.py:70 DeprecationWarning: This process (pid=2739) is multi-threaded, use of fork() may lead to deadlocks in the child.
[2025-03-10T16:20:59.400+0000] {standard_task_runner.py:72} INFO - Started process 2740 to run task
[2025-03-10T16:20:59.399+0000] {standard_task_runner.py:104} INFO - Running: ['***', 'tasks', 'run', 'xkcd_daily', 'dbt_run', 'manual__2025-03-10T14:20:39.848994+00:00', '--job-id', '161', '--raw', '--subdir', 'DAGS_FOLDER/XKCD_daily/dag.py', '--cfg-path', '/tmp/tmp_l81mfo_']
[2025-03-10T16:20:59.400+0000] {standard_task_runner.py:105} INFO - Job 161: Subtask dbt_run
[2025-03-10T16:20:59.416+0000] {logging_mixin.py:190} WARNING - /home/***/.local/lib/python3.12/site-packages/***/settings.py:209 DeprecationWarning: The sql_alchemy_conn option in [core] has been moved to the sql_alchemy_conn option in [database] - the old setting has been used, but please update your config.
[2025-03-10T16:20:59.459+0000] {task_command.py:467} INFO - Running <TaskInstance: xkcd_daily.dbt_run manual__2025-03-10T14:20:39.848994+00:00 [running]> on host 157a64d0872f
[2025-03-10T16:20:59.533+0000] {taskinstance.py:3134} INFO - Exporting env vars: AIRFLOW_CTX_DAG_OWNER='***' AIRFLOW_CTX_DAG_ID='xkcd_daily' AIRFLOW_CTX_TASK_ID='dbt_run' AIRFLOW_CTX_EXECUTION_DATE='2025-03-10T14:20:39.848994+00:00' AIRFLOW_CTX_TRY_NUMBER='14' AIRFLOW_CTX_DAG_RUN_ID='manual__2025-03-10T14:20:39.848994+00:00'
[2025-03-10T16:20:59.533+0000] {taskinstance.py:732} INFO - ::endgroup::
[2025-03-10T16:20:59.544+0000] {subprocess.py:78} INFO - Tmp dir root location: /tmp
[2025-03-10T16:20:59.544+0000] {subprocess.py:88} INFO - Running command: ['/usr/bin/bash', '-c', 'cd /dbt/transformations && dbt run --project-dir /dbt/transformations --profiles-dir /dbt']
[2025-03-10T16:20:59.550+0000] {subprocess.py:99} INFO - Output:
[2025-03-10T16:21:01.069+0000] {subprocess.py:106} INFO - [0m16:21:01  Running with dbt=1.9.3
[2025-03-10T16:21:01.282+0000] {subprocess.py:106} INFO - [0m16:21:01  Registered adapter: postgres=1.9.0
[2025-03-10T16:21:01.699+0000] {subprocess.py:106} INFO - [0m16:21:01  [[33mWARNING[0m]: Configuration paths exist in your dbt_project.yml file which do not apply to any resources.
[2025-03-10T16:21:01.701+0000] {subprocess.py:106} INFO - There are 1 unused configuration paths:
[2025-03-10T16:21:01.702+0000] {subprocess.py:106} INFO - - models.transformations.example
[2025-03-10T16:21:01.804+0000] {subprocess.py:106} INFO - [0m16:21:01  Found 5 models, 1 source, 433 macros
[2025-03-10T16:21:01.806+0000] {subprocess.py:106} INFO - [0m16:21:01
[2025-03-10T16:21:01.808+0000] {subprocess.py:106} INFO - [0m16:21:01  Concurrency: 1 threads (target='prod')
[2025-03-10T16:21:01.808+0000] {subprocess.py:106} INFO - [0m16:21:01
[2025-03-10T16:21:01.910+0000] {subprocess.py:106} INFO - [0m16:21:01  1 of 5 START sql table model dbt_dwh.dim_comics ................................ [RUN]
[2025-03-10T16:21:02.071+0000] {subprocess.py:106} INFO - [0m16:21:02  1 of 5 OK created sql table model dbt_dwh.dim_comics ........................... [[32mSELECT 561[0m in 0.16s]
[2025-03-10T16:21:02.072+0000] {subprocess.py:106} INFO - [0m16:21:02  2 of 5 START sql table model dbt_dwh.fact_cost ................................. [RUN]
[2025-03-10T16:21:02.140+0000] {subprocess.py:106} INFO - [0m16:21:02  2 of 5 OK created sql table model dbt_dwh.fact_cost ............................ [[32mSELECT 561[0m in 0.07s]
[2025-03-10T16:21:02.144+0000] {subprocess.py:106} INFO - [0m16:21:02  3 of 5 START sql table model dbt_dwh.fact_review ............................... [RUN]
[2025-03-10T16:21:02.248+0000] {subprocess.py:106} INFO - [0m16:21:02  3 of 5 OK created sql table model dbt_dwh.fact_review .......................... [[32mSELECT 561[0m in 0.10s]
[2025-03-10T16:21:02.249+0000] {subprocess.py:106} INFO - [0m16:21:02  4 of 5 START sql table model dbt_dwh.fact_views ................................ [RUN]
[2025-03-10T16:21:02.315+0000] {subprocess.py:106} INFO - [0m16:21:02  4 of 5 OK created sql table model dbt_dwh.fact_views ........................... [[32mSELECT 561[0m in 0.06s]
[2025-03-10T16:21:02.317+0000] {subprocess.py:106} INFO - [0m16:21:02  5 of 5 START sql view model dbt_dwh.dm_comic_overview .......................... [RUN]
[2025-03-10T16:21:02.369+0000] {subprocess.py:106} INFO - [0m16:21:02  5 of 5 ERROR creating sql view model dbt_dwh.dm_comic_overview ................. [[31mERROR[0m in 0.05s]
[2025-03-10T16:21:02.385+0000] {subprocess.py:106} INFO - [0m16:21:02
[2025-03-10T16:21:02.386+0000] {subprocess.py:106} INFO - [0m16:21:02  Finished running 4 table models, 1 view model in 0 hours 0 minutes and 0.58 seconds (0.58s).
[2025-03-10T16:21:02.425+0000] {subprocess.py:106} INFO - [0m16:21:02
[2025-03-10T16:21:02.426+0000] {subprocess.py:106} INFO - [0m16:21:02  [31mCompleted with 1 error, 0 partial successes, and 0 warnings:[0m
[2025-03-10T16:21:02.426+0000] {subprocess.py:106} INFO - [0m16:21:02
[2025-03-10T16:21:02.427+0000] {subprocess.py:106} INFO - [0m16:21:02    Database Error in model dm_comic_overview (models/comics/dm_comic_overview.sql)
[2025-03-10T16:21:02.427+0000] {subprocess.py:106} INFO -   syntax error at or near "comic_views"
[2025-03-10T16:21:02.427+0000] {subprocess.py:106} INFO -   LINE 32: comic_views AS (
[2025-03-10T16:21:02.427+0000] {subprocess.py:106} INFO -            ^
[2025-03-10T16:21:02.427+0000] {subprocess.py:106} INFO -   compiled code at target/run/transformations/models/comics/dm_comic_overview.sql
[2025-03-10T16:21:02.427+0000] {subprocess.py:106} INFO - [0m16:21:02
[2025-03-10T16:21:02.428+0000] {subprocess.py:106} INFO - [0m16:21:02  Done. PASS=4 WARN=0 ERROR=1 SKIP=0 TOTAL=5
[2025-03-10T16:21:03.130+0000] {subprocess.py:110} INFO - Command exited with return code 1
[2025-03-10T16:21:03.143+0000] {taskinstance.py:3313} ERROR - Task failed with exception
Traceback (most recent call last):
  File "/home/airflow/.local/lib/python3.12/site-packages/airflow/models/taskinstance.py", line 768, in _execute_task
    result = _execute_callable(context=context, **execute_callable_kwargs)
             ^^^^^^^^^^^^^^^^^^^^^^^^^^^^^^^^^^^^^^^^^^^^^^^^^^^^^^^^^^^^^
  File "/home/airflow/.local/lib/python3.12/site-packages/airflow/models/taskinstance.py", line 734, in _execute_callable
    return ExecutionCallableRunner(
           ^^^^^^^^^^^^^^^^^^^^^^^^
  File "/home/airflow/.local/lib/python3.12/site-packages/airflow/utils/operator_helpers.py", line 252, in run
    return self.func(*args, **kwargs)
           ^^^^^^^^^^^^^^^^^^^^^^^^^^
  File "/home/airflow/.local/lib/python3.12/site-packages/airflow/models/baseoperator.py", line 424, in wrapper
    return func(self, *args, **kwargs)
           ^^^^^^^^^^^^^^^^^^^^^^^^^^^
  File "/home/airflow/.local/lib/python3.12/site-packages/airflow/operators/bash.py", line 276, in execute
    raise AirflowException(
airflow.exceptions.AirflowException: Bash command failed. The command returned a non-zero exit code 1.
[2025-03-10T16:21:03.149+0000] {taskinstance.py:1226} INFO - Marking task as UP_FOR_RETRY. dag_id=xkcd_daily, task_id=dbt_run, run_id=manual__2025-03-10T14:20:39.848994+00:00, execution_date=20250310T142039, start_date=20250310T162059, end_date=20250310T162103
[2025-03-10T16:21:03.248+0000] {taskinstance.py:341} INFO - ::group::Post task execution logs
[2025-03-10T16:21:03.249+0000] {standard_task_runner.py:124} ERROR - Failed to execute job 161 for task dbt_run (Bash command failed. The command returned a non-zero exit code 1.; 2740)
Traceback (most recent call last):
  File "/home/airflow/.local/lib/python3.12/site-packages/airflow/task/task_runner/standard_task_runner.py", line 117, in _start_by_fork
    ret = args.func(args, dag=self.dag)
          ^^^^^^^^^^^^^^^^^^^^^^^^^^^^^
  File "/home/airflow/.local/lib/python3.12/site-packages/airflow/cli/cli_config.py", line 49, in command
    return func(*args, **kwargs)
           ^^^^^^^^^^^^^^^^^^^^^
  File "/home/airflow/.local/lib/python3.12/site-packages/airflow/utils/cli.py", line 116, in wrapper
    return f(*args, **kwargs)
           ^^^^^^^^^^^^^^^^^^
  File "/home/airflow/.local/lib/python3.12/site-packages/airflow/cli/commands/task_command.py", line 483, in task_run
    task_return_code = _run_task_by_selected_method(args, _dag, ti)
                       ^^^^^^^^^^^^^^^^^^^^^^^^^^^^^^^^^^^^^^^^^^^^
  File "/home/airflow/.local/lib/python3.12/site-packages/airflow/cli/commands/task_command.py", line 256, in _run_task_by_selected_method
    return _run_raw_task(args, ti)
           ^^^^^^^^^^^^^^^^^^^^^^^
  File "/home/airflow/.local/lib/python3.12/site-packages/airflow/cli/commands/task_command.py", line 341, in _run_raw_task
    return ti._run_raw_task(
           ^^^^^^^^^^^^^^^^^
  File "/home/airflow/.local/lib/python3.12/site-packages/airflow/utils/session.py", line 97, in wrapper
    return func(*args, session=session, **kwargs)
           ^^^^^^^^^^^^^^^^^^^^^^^^^^^^^^^^^^^^^^
  File "/home/airflow/.local/lib/python3.12/site-packages/airflow/models/taskinstance.py", line 3006, in _run_raw_task
    return _run_raw_task(
           ^^^^^^^^^^^^^^
  File "/home/airflow/.local/lib/python3.12/site-packages/airflow/models/taskinstance.py", line 274, in _run_raw_task
    TaskInstance._execute_task_with_callbacks(
  File "/home/airflow/.local/lib/python3.12/site-packages/airflow/models/taskinstance.py", line 3161, in _execute_task_with_callbacks
    result = self._execute_task(context, task_orig)
             ^^^^^^^^^^^^^^^^^^^^^^^^^^^^^^^^^^^^^^
  File "/home/airflow/.local/lib/python3.12/site-packages/airflow/models/taskinstance.py", line 3185, in _execute_task
    return _execute_task(self, context, task_orig)
           ^^^^^^^^^^^^^^^^^^^^^^^^^^^^^^^^^^^^^^^
  File "/home/airflow/.local/lib/python3.12/site-packages/airflow/models/taskinstance.py", line 768, in _execute_task
    result = _execute_callable(context=context, **execute_callable_kwargs)
             ^^^^^^^^^^^^^^^^^^^^^^^^^^^^^^^^^^^^^^^^^^^^^^^^^^^^^^^^^^^^^
  File "/home/airflow/.local/lib/python3.12/site-packages/airflow/models/taskinstance.py", line 734, in _execute_callable
    return ExecutionCallableRunner(
           ^^^^^^^^^^^^^^^^^^^^^^^^
  File "/home/airflow/.local/lib/python3.12/site-packages/airflow/utils/operator_helpers.py", line 252, in run
    return self.func(*args, **kwargs)
           ^^^^^^^^^^^^^^^^^^^^^^^^^^
  File "/home/airflow/.local/lib/python3.12/site-packages/airflow/models/baseoperator.py", line 424, in wrapper
    return func(self, *args, **kwargs)
           ^^^^^^^^^^^^^^^^^^^^^^^^^^^
  File "/home/airflow/.local/lib/python3.12/site-packages/airflow/operators/bash.py", line 276, in execute
    raise AirflowException(
airflow.exceptions.AirflowException: Bash command failed. The command returned a non-zero exit code 1.
[2025-03-10T16:21:03.264+0000] {local_task_job_runner.py:266} INFO - Task exited with return code 1
[2025-03-10T16:21:03.286+0000] {taskinstance.py:3901} INFO - 0 downstream tasks scheduled from follow-on schedule check
[2025-03-10T16:21:03.290+0000] {local_task_job_runner.py:245} INFO - ::endgroup::
